 Thu, 09 Aug 2018 17:50:50  INFO myLogger2.py <module> [ line:22 ] hehehe
 Thu, 09 Aug 2018 17:50:51  INFO test_api_v1.py test_register [ line:43 ] ========开始一个接口测试========
 Thu, 09 Aug 2018 17:50:51  INFO test_api_v1.py test_register [ line:44 ] 请求url为：
http://120.79.176.157:8080/futureloan/mvc/api/member/register
 Thu, 09 Aug 2018 17:50:51  INFO test_api_v1.py test_register [ line:45 ] 请求方法为：get
 Thu, 09 Aug 2018 17:50:51  INFO test_api_v1.py test_register [ line:46 ] 请求数据为：
{"mobilephone":"15511000348","pwd":"12345678"}
 Thu, 09 Aug 2018 17:50:51  INFO test_api_v1.py test_register [ line:49 ] 响应的结果为：
{"status":0,"code":"20110","data":null,"msg":"手机号码已被注册"}
 Thu, 09 Aug 2018 17:50:51  ERROR test_api_v1.py test_register [ line:59 ] 期望结果与实际结果不匹配，用例失败！
 Thu, 09 Aug 2018 17:50:51  ERROR test_api_v1.py test_register [ line:60 ] 断言异常：
Traceback (most recent call last):
  File "/Applications/PyCharm CE.app/Contents/helpers/pycharm/teamcity/diff_tools.py", line 30, in _patched_equals
    old(self, first, second, msg)
  File "/Library/Frameworks/Python.framework/Versions/3.6/lib/python3.6/unittest/case.py", line 829, in assertEqual
    assertion_func(first, second, msg=msg)
  File "/Library/Frameworks/Python.framework/Versions/3.6/lib/python3.6/unittest/case.py", line 1203, in assertMultiLineEqual
    self.fail(self._formatMessage(msg, standardMsg))
  File "/Library/Frameworks/Python.framework/Versions/3.6/lib/python3.6/unittest/case.py", line 670, in fail
    raise self.failureException(msg)
AssertionError: '{"status":1,"code":"10001","data":null,"msg":"注册成功"}' != '{"status":0,"code":"20110","data":null,"msg":"手机号码已被注册"}'
- {"status":1,"code":"10001","data":null,"msg":"注册成功"}
?           ^           ---                       --
+ {"status":0,"code":"20110","data":null,"msg":"手机号码已被注册"}
?           ^         +++                       ++++++


During handling of the above exception, another exception occurred:

Traceback (most recent call last):
  File "/Users/gemii/TestProjects/API_Framework/TestCases/test_api_v1.py", line 56, in test_register
    self.assertEqual(casedata["expected_data"],res_obj.text)  # text获取响应体
  File "/Applications/PyCharm CE.app/Contents/helpers/pycharm/teamcity/diff_tools.py", line 36, in _patched_equals
    raise error
teamcity.diff_tools.EqualsAssertionError:  :: {"status":1,"code":"10001","data":null,"msg":"注册成功"} != {"status":0,"code":"20110","data":null,"msg":"手机号码已被注册"}
 Thu, 09 Aug 2018 17:50:54  INFO test_api_v1.py test_register [ line:43 ] ========开始一个接口测试========
 Thu, 09 Aug 2018 17:50:54  INFO test_api_v1.py test_register [ line:44 ] 请求url为：
http://120.79.176.157:8080/futureloan/mvc/api/member/register
 Thu, 09 Aug 2018 17:50:54  INFO test_api_v1.py test_register [ line:45 ] 请求方法为：get
 Thu, 09 Aug 2018 17:50:54  INFO test_api_v1.py test_register [ line:46 ] 请求数据为：
{"mobilephone":"15511000349","pwd":"12345678","regname":"Cheese"}
 Thu, 09 Aug 2018 17:50:54  INFO test_api_v1.py test_register [ line:49 ] 响应的结果为：
{"status":0,"code":"20110","data":null,"msg":"手机号码已被注册"}
 Thu, 09 Aug 2018 17:50:54  ERROR test_api_v1.py test_register [ line:59 ] 期望结果与实际结果不匹配，用例失败！
 Thu, 09 Aug 2018 17:50:54  ERROR test_api_v1.py test_register [ line:60 ] 断言异常：
Traceback (most recent call last):
  File "/Applications/PyCharm CE.app/Contents/helpers/pycharm/teamcity/diff_tools.py", line 30, in _patched_equals
    old(self, first, second, msg)
  File "/Library/Frameworks/Python.framework/Versions/3.6/lib/python3.6/unittest/case.py", line 829, in assertEqual
    assertion_func(first, second, msg=msg)
  File "/Library/Frameworks/Python.framework/Versions/3.6/lib/python3.6/unittest/case.py", line 1203, in assertMultiLineEqual
    self.fail(self._formatMessage(msg, standardMsg))
  File "/Library/Frameworks/Python.framework/Versions/3.6/lib/python3.6/unittest/case.py", line 670, in fail
    raise self.failureException(msg)
AssertionError: '{"status":1,"code":"10001","data":null,"msg":"注册成功"}' != '{"status":0,"code":"20110","data":null,"msg":"手机号码已被注册"}'
- {"status":1,"code":"10001","data":null,"msg":"注册成功"}
?           ^           ---                       --
+ {"status":0,"code":"20110","data":null,"msg":"手机号码已被注册"}
?           ^         +++                       ++++++


During handling of the above exception, another exception occurred:

Traceback (most recent call last):
  File "/Users/gemii/TestProjects/API_Framework/TestCases/test_api_v1.py", line 56, in test_register
    self.assertEqual(casedata["expected_data"],res_obj.text)  # text获取响应体
  File "/Applications/PyCharm CE.app/Contents/helpers/pycharm/teamcity/diff_tools.py", line 36, in _patched_equals
    raise error
teamcity.diff_tools.EqualsAssertionError:  :: {"status":1,"code":"10001","data":null,"msg":"注册成功"} != {"status":0,"code":"20110","data":null,"msg":"手机号码已被注册"}
 Thu, 09 Aug 2018 17:50:57  INFO test_api_v1.py test_register [ line:43 ] ========开始一个接口测试========
 Thu, 09 Aug 2018 17:50:57  INFO test_api_v1.py test_register [ line:44 ] 请求url为：
http://120.79.176.157:8080/futureloan/mvc/api/member/register
 Thu, 09 Aug 2018 17:50:57  INFO test_api_v1.py test_register [ line:45 ] 请求方法为：get
 Thu, 09 Aug 2018 17:50:57  INFO test_api_v1.py test_register [ line:46 ] 请求数据为：
{"mobilephone":"","pwd":"12345678"}
 Thu, 09 Aug 2018 17:50:57  INFO test_api_v1.py test_register [ line:49 ] 响应的结果为：
{"status":0,"code":"20103","data":null,"msg":"手机号不能为空"}
 Thu, 09 Aug 2018 17:50:57  INFO test_api_v1.py test_register [ line:57 ] 期望结果与实际结果匹配，用例成功！
